2023-09-10 15:59:09 -03 [INFO] -- backend_pre_start.py[45] --  Initializing service
2023-09-10 15:59:09 -03 [INFO] -- before.py[27] --  Starting call to '__main__.init', this is the 1st time calling it.
2023-09-10 15:59:09 -03 [INFO] -- backend_pre_start.py[47] --  Service finished initializing
2023-09-10 15:59:59 -03 [INFO] -- backend_pre_start.py[45] --  Initializing service
2023-09-10 15:59:59 -03 [INFO] -- before.py[27] --  Starting call to '__main__.init', this is the 1st time calling it.
2023-09-10 15:59:59 -03 [ERROR] -- backend_pre_start.py[40] --  (psycopg2.OperationalError) could not connect to server: Connection refused
	Is the server running on host "db" (172.29.0.7) and accepting
	TCP/IP connections on port 5432?

(Background on this error at: https://sqlalche.me/e/20/e3q8)
2023-09-10 15:59:59 -03 [WARNING] -- after.py[30] --  Finished call to '__main__.init' after 0.001(s), this was the 1st time calling it.
2023-09-10 16:00:00 -03 [INFO] -- before.py[27] --  Starting call to '__main__.init', this is the 2nd time calling it.
2023-09-10 16:00:00 -03 [INFO] -- backend_pre_start.py[47] --  Service finished initializing
2023-09-11 19:09:45 -03 [INFO] -- backend_pre_start.py[45] --  Initializing service
2023-09-11 19:09:45 -03 [INFO] -- before.py[27] --  Starting call to '__main__.init', this is the 1st time calling it.
2023-09-11 19:09:45 -03 [INFO] -- backend_pre_start.py[47] --  Service finished initializing
2023-09-12 19:06:47 -03 [INFO] -- backend_pre_start.py[45] --  Initializing service
2023-09-12 19:06:47 -03 [INFO] -- before.py[27] --  Starting call to '__main__.init', this is the 1st time calling it.
2023-09-12 19:06:47 -03 [INFO] -- backend_pre_start.py[47] --  Service finished initializing
2023-09-12 19:18:26 -03 [INFO] -- backend_pre_start.py[45] --  Initializing service
2023-09-12 19:18:26 -03 [INFO] -- before.py[27] --  Starting call to '__main__.init', this is the 1st time calling it.
2023-09-12 19:18:26 -03 [INFO] -- backend_pre_start.py[47] --  Service finished initializing
2023-09-12 19:20:33 -03 [INFO] -- backend_pre_start.py[45] --  Initializing service
2023-09-12 19:20:33 -03 [INFO] -- before.py[27] --  Starting call to '__main__.init', this is the 1st time calling it.
2023-09-12 19:20:33 -03 [INFO] -- backend_pre_start.py[47] --  Service finished initializing
2023-09-13 18:57:46 -03 [INFO] -- backend_pre_start.py[45] --  Initializing service
2023-09-13 18:57:46 -03 [INFO] -- before.py[27] --  Starting call to '__main__.init', this is the 1st time calling it.
2023-09-13 18:57:46 -03 [INFO] -- backend_pre_start.py[47] --  Service finished initializing
2023-09-13 19:52:21 -03 [INFO] -- backend_pre_start.py[45] --  Initializing service
2023-09-13 19:52:21 -03 [INFO] -- before.py[27] --  Starting call to '__main__.init', this is the 1st time calling it.
2023-09-13 19:52:21 -03 [INFO] -- backend_pre_start.py[47] --  Service finished initializing
2023-09-13 19:53:18 -03 [INFO] -- backend_pre_start.py[45] --  Initializing service
2023-09-13 19:53:18 -03 [INFO] -- before.py[27] --  Starting call to '__main__.init', this is the 1st time calling it.
2023-09-13 19:53:18 -03 [INFO] -- backend_pre_start.py[47] --  Service finished initializing
2023-09-13 20:17:10 -03 [INFO] -- backend_pre_start.py[45] --  Initializing service
2023-09-13 20:17:10 -03 [INFO] -- before.py[27] --  Starting call to '__main__.init', this is the 1st time calling it.
2023-09-13 20:17:10 -03 [INFO] -- backend_pre_start.py[47] --  Service finished initializing
2023-09-13 20:19:42 -03 [INFO] -- backend_pre_start.py[45] --  Initializing service
2023-09-13 20:19:42 -03 [INFO] -- before.py[27] --  Starting call to '__main__.init', this is the 1st time calling it.
2023-09-13 20:19:42 -03 [INFO] -- backend_pre_start.py[47] --  Service finished initializing
2023-09-13 20:20:11 -03 [INFO] -- backend_pre_start.py[45] --  Initializing service
2023-09-13 20:20:11 -03 [INFO] -- before.py[27] --  Starting call to '__main__.init', this is the 1st time calling it.
2023-09-13 20:20:11 -03 [INFO] -- backend_pre_start.py[47] --  Service finished initializing
2023-09-13 20:21:19 -03 [INFO] -- backend_pre_start.py[45] --  Initializing service
2023-09-13 20:21:19 -03 [INFO] -- before.py[27] --  Starting call to '__main__.init', this is the 1st time calling it.
2023-09-13 20:21:19 -03 [INFO] -- backend_pre_start.py[47] --  Service finished initializing
2023-09-13 20:59:44 -03 [INFO] -- backend_pre_start.py[45] --  Initializing service
2023-09-13 20:59:44 -03 [INFO] -- before.py[27] --  Starting call to '__main__.init', this is the 1st time calling it.
2023-09-13 20:59:44 -03 [INFO] -- backend_pre_start.py[47] --  Service finished initializing
2023-09-13 21:00:55 -03 [INFO] -- backend_pre_start.py[45] --  Initializing service
2023-09-13 21:00:55 -03 [INFO] -- before.py[27] --  Starting call to '__main__.init', this is the 1st time calling it.
2023-09-13 21:00:55 -03 [INFO] -- backend_pre_start.py[47] --  Service finished initializing
2023-09-13 21:02:03 -03 [INFO] -- backend_pre_start.py[45] --  Initializing service
2023-09-13 21:02:03 -03 [INFO] -- before.py[27] --  Starting call to '__main__.init', this is the 1st time calling it.
2023-09-13 21:02:03 -03 [INFO] -- backend_pre_start.py[47] --  Service finished initializing
2023-09-13 21:03:19 -03 [INFO] -- backend_pre_start.py[45] --  Initializing service
2023-09-13 21:03:19 -03 [INFO] -- before.py[27] --  Starting call to '__main__.init', this is the 1st time calling it.
2023-09-13 21:03:19 -03 [INFO] -- backend_pre_start.py[47] --  Service finished initializing
2023-09-13 21:05:06 -03 [INFO] -- backend_pre_start.py[45] --  Initializing service
2023-09-13 21:05:06 -03 [INFO] -- before.py[27] --  Starting call to '__main__.init', this is the 1st time calling it.
2023-09-13 21:05:06 -03 [INFO] -- backend_pre_start.py[47] --  Service finished initializing
2023-09-13 21:05:48 -03 [INFO] -- backend_pre_start.py[45] --  Initializing service
2023-09-13 21:05:48 -03 [INFO] -- before.py[27] --  Starting call to '__main__.init', this is the 1st time calling it.
2023-09-13 21:05:48 -03 [INFO] -- backend_pre_start.py[47] --  Service finished initializing
2023-09-13 21:07:10 -03 [INFO] -- backend_pre_start.py[45] --  Initializing service
2023-09-13 21:07:10 -03 [INFO] -- before.py[27] --  Starting call to '__main__.init', this is the 1st time calling it.
2023-09-13 21:07:10 -03 [INFO] -- backend_pre_start.py[47] --  Service finished initializing
2023-09-13 21:07:51 -03 [INFO] -- backend_pre_start.py[45] --  Initializing service
2023-09-13 21:07:51 -03 [INFO] -- before.py[27] --  Starting call to '__main__.init', this is the 1st time calling it.
2023-09-13 21:07:51 -03 [INFO] -- backend_pre_start.py[47] --  Service finished initializing
2023-09-13 21:09:06 -03 [INFO] -- backend_pre_start.py[45] --  Initializing service
2023-09-13 21:09:06 -03 [INFO] -- before.py[27] --  Starting call to '__main__.init', this is the 1st time calling it.
2023-09-13 21:09:06 -03 [INFO] -- backend_pre_start.py[47] --  Service finished initializing
2023-09-13 21:11:56 -03 [INFO] -- backend_pre_start.py[45] --  Initializing service
2023-09-13 21:11:56 -03 [INFO] -- before.py[27] --  Starting call to '__main__.init', this is the 1st time calling it.
2023-09-13 21:11:56 -03 [INFO] -- backend_pre_start.py[47] --  Service finished initializing
2023-09-13 21:12:48 -03 [INFO] -- backend_pre_start.py[45] --  Initializing service
2023-09-13 21:12:48 -03 [INFO] -- before.py[27] --  Starting call to '__main__.init', this is the 1st time calling it.
2023-09-13 21:12:48 -03 [INFO] -- backend_pre_start.py[47] --  Service finished initializing
2023-09-14 18:49:57 -03 [INFO] -- backend_pre_start.py[45] --  Initializing service
2023-09-14 18:49:57 -03 [INFO] -- before.py[27] --  Starting call to '__main__.init', this is the 1st time calling it.
2023-09-14 18:49:57 -03 [INFO] -- backend_pre_start.py[47] --  Service finished initializing
2023-09-14 19:37:35 -03 [INFO] -- backend_pre_start.py[45] --  Initializing service
2023-09-14 19:37:35 -03 [INFO] -- before.py[27] --  Starting call to '__main__.init', this is the 1st time calling it.
2023-09-14 19:37:35 -03 [ERROR] -- backend_pre_start.py[40] --  (psycopg2.OperationalError) could not connect to server: Connection refused
	Is the server running on host "db" (172.29.0.7) and accepting
	TCP/IP connections on port 5432?

(Background on this error at: https://sqlalche.me/e/20/e3q8)
2023-09-14 19:37:35 -03 [WARNING] -- after.py[30] --  Finished call to '__main__.init' after 0.001(s), this was the 1st time calling it.
2023-09-14 19:37:36 -03 [INFO] -- before.py[27] --  Starting call to '__main__.init', this is the 2nd time calling it.
2023-09-14 19:37:36 -03 [INFO] -- backend_pre_start.py[47] --  Service finished initializing
2023-09-14 19:43:14 -03 [INFO] -- backend_pre_start.py[45] --  Initializing service
2023-09-14 19:43:14 -03 [INFO] -- before.py[27] --  Starting call to '__main__.init', this is the 1st time calling it.
2023-09-14 19:43:14 -03 [ERROR] -- backend_pre_start.py[40] --  (psycopg2.OperationalError) could not connect to server: Connection refused
	Is the server running on host "db" (172.29.0.7) and accepting
	TCP/IP connections on port 5432?

(Background on this error at: https://sqlalche.me/e/20/e3q8)
2023-09-14 19:43:14 -03 [WARNING] -- after.py[30] --  Finished call to '__main__.init' after 0.001(s), this was the 1st time calling it.
2023-09-14 19:43:15 -03 [INFO] -- before.py[27] --  Starting call to '__main__.init', this is the 2nd time calling it.
2023-09-14 19:43:15 -03 [INFO] -- backend_pre_start.py[47] --  Service finished initializing
2023-09-15 19:17:10 -03 [INFO] -- backend_pre_start.py[45] --  Initializing service
2023-09-15 19:17:10 -03 [INFO] -- before.py[27] --  Starting call to '__main__.init', this is the 1st time calling it.
2023-09-15 19:17:10 -03 [INFO] -- backend_pre_start.py[47] --  Service finished initializing
2023-09-15 19:45:43 -03 [INFO] -- backend_pre_start.py[45] --  Initializing service
2023-09-15 19:45:43 -03 [INFO] -- before.py[27] --  Starting call to '__main__.init', this is the 1st time calling it.
2023-09-15 19:45:43 -03 [ERROR] -- backend_pre_start.py[40] --  (psycopg2.OperationalError) could not connect to server: Connection refused
	Is the server running on host "db" (172.29.0.7) and accepting
	TCP/IP connections on port 5432?

(Background on this error at: https://sqlalche.me/e/20/e3q8)
2023-09-15 19:45:43 -03 [WARNING] -- after.py[30] --  Finished call to '__main__.init' after 0.001(s), this was the 1st time calling it.
2023-09-15 19:45:44 -03 [INFO] -- before.py[27] --  Starting call to '__main__.init', this is the 2nd time calling it.
2023-09-15 19:45:44 -03 [INFO] -- backend_pre_start.py[47] --  Service finished initializing
